Workbook

Sheet plan
B2: 46244 | I2: =B2+1 -> 46245 | P2: =B2+2 -> 46246 | W2: =B2+3 -> 46247
A3: 1 | B3: Πρ | C3: Άφιξη | H3: 5 | I3: Πρ | O3: 9 | P3: Πρ | V3: 13 | W3: Πρ
A4: 2 | H4: 6 | O4: 10 | V4: 14
A5: 3 | B5: Aπ | H5: 7 | I5: Aπ | O5: 11 | P5: Aπ | V5: 15 | W5: Aπ
A6: 4 | H6: 8 | O6: 12 | V6: 16
B8: =B2+4 -> 46248 | I8: =B2+5 -> 46249 | P8: =B2+6 -> 46250 | W8: =B2+7 -> 46251
A9: 17 | B9: Πρ | H9: 21 | I9: Πρ | O9: 25 | P9: Πρ | V9: 29 | W9: Πρ
A10: 18 | H10: 22 | O10: 26 | V10: 30
A11: 19 | B11: Aπ | H11: 23 | I11: Aπ | O11: 27 | P11: Aπ | V11: 31 | W11: Aπ
A12: 20 | H12: 24 | O12: 28 | V12: 32
B14: =B2+8 -> 46252 | I14: =B2+9 -> 46253 | P14: =B2+10 -> 46254 | W14: =B2+11 -> 46255
A15: 33 | B15: Πρ | H15: 37 | I15: Πρ | O15: 41 | P15: Πρ | V15: 45 | W15: Πρ
A16: 34 | H16: 38 | O16: 42 | V16: 46
A17: 35 | B17: Aπ | H17: 39 | I17: Aπ | O17: 43 | P17: Aπ | V17: 47 | W17: Aπ
A18: 36 | H18: 40 | O18: 44 | V18: 48

Sheet teams
A1: id | B1: name | C1: char
A2: 1 | C2: 1
A3: 2 | C3: 2
A4: 3 | C4: 3
A5: 4 | C5: 4
A6: 5 | C6: 5
A7: 6 | C7: 6
A8: 7 | C8: 7
A9: 8 | C9: 8
A10: 9 | C10: 9
A11: 10 | C11: A

Sheet fields
A1: field | B1: name | C1: color | D1: column | E1: char
A2: fold | B2: Π Ποδόσφαιρο | C2: yellow | D2: 1 | E2: p
A3: fnew | B3: Κ Ποδόσφαιρο | C3: green | D3: 2 | E3: p
A4: bask | B4: Μπάσκετ | C4: blue | D4: 3 | E4: k
A5: voll | B5: Βόλεϊ | C5: orange | D5: 4 | E5: v
A6: base | B6: Μπέιζμπολ | C6: pink | D6: 5 | E6: m

Sheet games
A1: r | B1: field | C1: col | D1: pair | E1: tag | F1: ind | G1: played | H1: th | I1: ta | J1: sh | K1: sa | L1: sport
A2: 1 | B2: fold | C2: =INDEX(fields[column],MATCH(games[[#This Row],[field]],fields[field],0)) -> 1 | D2: =_xlfn.IFNA(OFFSET(plan!$A$1,MATCH(games[[#This Row],[r]],plan!A:A,0)-1,games[[#This Row],[col]]+1+0),_xlfn.IFNA(OFFSET(plan!$A$1,MATCH(games[[#This Row],[r]],plan!H:H,0)-1,games[[#This Row],[col]]+1+7),_xlfn.IFNA(OFFSET(plan!$A$1,MATCH(games[[#This Row],[r]],plan!O:O,0)-1,games[[#This Row],[col]]+1+14),_xlfn.IFNA(OFFSET(plan!$A$1,MATCH(games[[#This Row],[r]],plan!V:V,0)-1,games[[#This Row],[col]]+1+21),"")))) -> Άφιξη | E2: =IF(LEN(games[[#This Row],[pair]])=3,MID(games[[#This Row],[pair]],2,1),"") | F2: {=MATCH(1,(pages!$A$1:$A$957=games[[#This Row],[r]])*(pages!$B$1:$B$957=games[[#This Row],[field]]),0)} -> 4 | G2: =INDEX(pages!$L$1:$L$957,games[[#This Row],[ind]]) -> FALSE | H2: =_xlfn.IFNA(IF(LEN(games[[#This Row],[pair]])=3,INDEX(teams[id],MATCH(LEFT(games[[#This Row],[pair]]),teams[char],0)),""),"") | I2: =_xlfn.IFNA(IF(LEN(games[[#This Row],[pair]])=3,INDEX(teams[id],MATCH(RIGHT(games[[#This Row],[pair]]),teams[char],0)),""),"") | J2: =IF(games[[#This Row],[played]],INDEX(pages!$I$1:$I$759,games[[#This Row],[ind]]),"") | K2: =IF(games[[#This Row],[played]],INDEX(pages!$J$1:$J$759,games[[#This Row],[ind]]),"") | L2: =INDEX(fields[char],MATCH(games[[#This Row],[field]],fields[field],0))&IF(games[[#This Row],[tag]]="-","","("&games[[#This Row],[tag]]&")") -> p()
A3: 1 | B3: fnew | C3: =INDEX(fields[column],MATCH(games[[#This Row],[field]],fields[field],0)) -> 2 | D3: =_xlfn.IFNA(OFFSET(plan!$A$1,MATCH(games[[#This Row],[r]],plan!A:A,0)-1,games[[#This Row],[col]]+1+0),_xlfn.IFNA(OFFSET(plan!$A$1,MATCH(games[[#This Row],[r]],plan!H:H,0)-1,games[[#This Row],[col]]+1+7),_xlfn.IFNA(OFFSET(plan!$A$1,MATCH(games[[#This Row],[r]],plan!O:O,0)-1,games[[#This Row],[col]]+1+14),_xlfn.IFNA(OFFSET(plan!$A$1,MATCH(games[[#This Row],[r]],plan!V:V,0)-1,games[[#This Row],[col]]+1+21),"")))) -> 0 | E3: =IF(LEN(games[[#This Row],[pair]])=3,MID(games[[#This Row],[pair]],2,1),"") | F3: {=MATCH(1,(pages!$A$1:$A$957=games[[#This Row],[r]])*(pages!$B$1:$B$957=games[[#This Row],[field]]),0)} -> 5 | G3: =INDEX(pages!$L$1:$L$957,games[[#This Row],[ind]]) -> FALSE | H3: =_xlfn.IFNA(IF(LEN(games[[#This Row],[pair]])=3,INDEX(teams[id],MATCH(LEFT(games[[#This Row],[pair]]),teams[char],0)),""),"") | I3: =_xlfn.IFNA(IF(LEN(games[[#This Row],[pair]])=3,INDEX(teams[id],MATCH(RIGHT(games[[#This Row],[pair]]),teams[char],0)),""),"") | J3: =IF(games[[#This Row],[played]],INDEX(pages!$I$1:$I$759,games[[#This Row],[ind]]),"") | K3: =IF(games[[#This Row],[played]],INDEX(pages!$J$1:$J$759,games[[#This Row],[ind]]),"") | L3: =INDEX(fields[char],MATCH(games[[#This Row],[field]],fields[field],0))&IF(games[[#This Row],[tag]]="-","","("&games[[#This Row],[tag]]&")") -> p()
A4: 1 | B4: bask | C4: =INDEX(fields[column],MATCH(games[[#This Row],[field]],fields[field],0)) -> 3 | D4: =_xlfn.IFNA(OFFSET(plan!$A$1,MATCH(games[[#This Row],[r]],plan!A:A,0)-1,games[[#This Row],[col]]+1+0),_xlfn.IFNA(OFFSET(plan!$A$1,MATCH(games[[#This Row],[r]],plan!H:H,0)-1,games[[#This Row],[col]]+1+7),_xlfn.IFNA(OFFSET(plan!$A$1,MATCH(games[[#This Row],[r]],plan!O:O,0)-1,games[[#This Row],[col]]+1+14),_xlfn.IFNA(OFFSET(plan!$A$1,MATCH(games[[#This Row],[r]],plan!V:V,0)-1,games[[#This Row],[col]]+1+21),"")))) -> 0 | E4: =IF(LEN(games[[#This Row],[pair]])=3,MID(games[[#This Row],[pair]],2,1),"") | F4: {=MATCH(1,(pages!$A$1:$A$957=games[[#This Row],[r]])*(pages!$B$1:$B$957=games[[#This Row],[field]]),0)} -> 6 | G4: =INDEX(pages!$L$1:$L$957,games[[#This Row],[ind]]) -> FALSE | H4: =_xlfn.IFNA(IF(LEN(games[[#This Row],[pair]])=3,INDEX(teams[id],MATCH(LEFT(games[[#This Row],[pair]]),teams[char],0)),""),"") | I4: =_xlfn.IFNA(IF(LEN(games[[#This Row],[pair]])=3,INDEX(teams[id],MATCH(RIGHT(games[[#This Row],[pair]]),teams[char],0)),""),"") | J4: =IF(games[[#This Row],[played]],INDEX(pages!$I$1:$I$759,games[[#This Row],[ind]]),"") | K4: =IF(games[[#This Row],[played]],INDEX(pages!$J$1:$J$759,games[[#This Row],[ind]]),"") | L4: =INDEX(fields[char],MATCH(games[[#This Row],[field]],fields[field],0))&IF(games[[#This Row],[tag]]="-","","("&games[[#This Row],[tag]]&")") -> k()
A5: 1 | B5: voll | C5: =INDEX(fields[column],MATCH(games[[#This Row],[field]],fields[field],0)) -> 4 | D5: =_xlfn.IFNA(OFFSET(plan!$A$1,MATCH(games[[#This Row],[r]],plan!A:A,0)-1,games[[#This Row],[col]]+1+0),_xlfn.IFNA(OFFSET(plan!$A$1,MATCH(games[[#This Row],[r]],plan!H:H,0)-1,games[[#This Row],[col]]+1+7),_xlfn.IFNA(OFFSET(plan!$A$1,MATCH(games[[#This Row],[r]],plan!O:O,0)-1,games[[#This Row],[col]]+1+14),_xlfn.IFNA(OFFSET(plan!$A$1,MATCH(games[[#This Row],[r]],plan!V:V,0)-1,games[[#This Row],[col]]+1+21),"")))) -> 0 | E5: =IF(LEN(games[[#This Row],[pair]])=3,MID(games[[#This Row],[pair]],2,1),"") | F5: {=MATCH(1,(pages!$A$1:$A$957=games[[#This Row],[r]])*(pages!$B$1:$B$957=games[[#This Row],[field]]),0)} -> 7 | G5: =INDEX(pages!$L$1:$L$957,games[[#This Row],[ind]]) -> FALSE | H5: =_xlfn.IFNA(IF(LEN(games[[#This Row],[pair]])=3,INDEX(teams[id],MATCH(LEFT(games[[#This Row],[pair]]),teams[char],0)),""),"") | I5: =_xlfn.IFNA(IF(LEN(games[[#This Row],[pair]])=3,INDEX(teams[id],MATCH(RIGHT(games[[#This Row],[pair]]),teams[char],0)),""),"") | J5: =IF(games[[#This Row],[played]],INDEX(pages!$I$1:$I$759,games[[#This Row],[ind]]),"") | K5: =IF(games[[#This Row],[played]],INDEX(pages!$J$1:$J$759,games[[#This Row],[ind]]),"") | L5: =INDEX(fields[char],MATCH(games[[#This Row],[field]],fields[field],0))&IF(games[[#This Row],[tag]]="-","","("&games[[#This Row],[tag]]&")") -> v()
A6: 1 | B6: base | C6: =INDEX(fields[column],MATCH(games[[#This Row],[field]],fields[field],0)) -> 5 | D6: =_xlfn.IFNA(OFFSET(plan!$A$1,MATCH(games[[#This Row],[r]],plan!A:A,0)-1,games[[#This Row],[col]]+1+0),_xlfn.IFNA(OFFSET(plan!$A$1,MATCH(games[[#This Row],[r]],plan!H:H,0)-1,games[[#This Row],[col]]+1+7),_xlfn.IFNA(OFFSET(plan!$A$1,MATCH(games[[#This Row],[r]],plan!O:O,0)-1,games[[#This Row],[col]]+1+14),_xlfn.IFNA(OFFSET(plan!$A$1,MATCH(games[[#This Row],[r]],plan!V:V,0)-1,games[[#This Row],[col]]+1+21),"")))) -> 0 | E6: =IF(LEN(games[[#This Row],[pair]])=3,MID(games[[#This Row],[pair]],2,1),"") | F6: {=MATCH(1,(pages!$A$1:$A$957=games[[#This Row],[r]])*(pages!$B$1:$B$957=games[[#This Row],[field]]),0)} -> 8 | G6: =INDEX(pages!$L$1:$L$957,games[[#This Row],[ind]]) -> FALSE | H6: =_xlfn.IFNA(IF(LEN(games[[#This Row],[pair]])=3,INDEX(teams[id],MATCH(LEFT(games[[#This Row],[pair]]),teams[char],0)),""),"") | I6: =_xlfn.IFNA(IF(LEN(games[[#This Row],[pair]])=3,INDEX(teams[id],MATCH(RIGHT(games[[#This Row],[pair]]),teams[char],0)),""),"") | J6: =IF(games[[#This Row],[played]],INDEX(pages!$I$1:$I$759,games[[#This Row],[ind]]),"") | K6: =IF(games[[#This Row],[played]],INDEX(pages!$J$1:$J$759,games[[#This Row],[ind]]),"") | L6: =INDEX(fields[char],MATCH(games[[#This Row],[field]],fields[field],0))&IF(games[[#This Row],[tag]]="-","","("&games[[#This Row],[tag]]&")") -> m()
A7: =A2+1 -> 2 | B7: fold | C7: =INDEX(fields[column],MATCH(games[[#This Row],[field]],fields[field],0)) -> 1 | D7: =_xlfn.IFNA(OFFSET(plan!$A$1,MATCH(games[[#This Row],[r]],plan!A:A,0)-1,games[[#This Row],[col]]+1+0),_xlfn.IFNA(OFFSET(plan!$A$1,MATCH(games[[#This Row],[r]],plan!H:H,0)-1,games[[#This Row],[col]]+1+7),_xlfn.IFNA(OFFSET(plan!$A$1,MATCH(games[[#This Row],[r]],plan!O:O,0)-1,games[[#This Row],[col]]+1+14),_xlfn.IFNA(OFFSET(plan!$A$1,MATCH(games[[#This Row],[r]],plan!V:V,0)-1,games[[#This Row],[col]]+1+21),"")))) -> 0 | E7: =IF(LEN(games[[#This Row],[pair]])=3,MID(games[[#This Row],[pair]],2,1),"") | F7: {=MATCH(1,(pages!$A$1:$A$957=games[[#This Row],[r]])*(pages!$B$1:$B$957=games[[#This Row],[field]]),0)} -> 9 | G7: =INDEX(pages!$L$1:$L$957,games[[#This Row],[ind]]) -> FALSE | H7: =_xlfn.IFNA(IF(LEN(games[[#This Row],[pair]])=3,INDEX(teams[id],MATCH(LEFT(games[[#This Row],[pair]]),teams[char],0)),""),"") | I7: =_xlfn.IFNA(IF(LEN(games[[#This Row],[pair]])=3,INDEX(teams[id],MATCH(RIGHT(games[[#This Row],[pair]]),teams[char],0)),""),"") | J7: =IF(games[[#This Row],[played]],INDEX(pages!$I$1:$I$759,games[[#This Row],[ind]]),"") | K7: =IF(games[[#This Row],[played]],INDEX(pages!$J$1:$J$759,games[[#This Row],[ind]]),"") | L7: =INDEX(fields[char],MATCH(games[[#This Row],[field]],fields[field],0))&IF(games[[#This Row],[tag]]="-","","("&games[[#This Row],[tag]]&")") -> p()
A8: =A3+1 -> 2 | B8: fnew | C8: =INDEX(fields[column],MATCH(games[[#This Row],[field]],fields[field],0)) -> 2 | D8: =_xlfn.IFNA(OFFSET(plan!$A$1,MATCH(games[[#This Row],[r]],plan!A:A,0)-1,games[[#This Row],[col]]+1+0),_xlfn.IFNA(OFFSET(plan!$A$1,MATCH(games[[#This Row],[r]],plan!H:H,0)-1,games[[#This Row],[col]]+1+7),_xlfn.IFNA(OFFSET(plan!$A$1,MATCH(games[[#This Row],[r]],plan!O:O,0)-1,games[[#This Row],[col]]+1+14),_xlfn.IFNA(OFFSET(plan!$A$1,MATCH(games[[#This Row],[r]],plan!V:V,0)-1,games[[#This Row],[col]]+1+21),"")))) -> 0 | E8: =IF(LEN(games[[#This Row],[pair]])=3,MID(games[[#This Row],[pair]],2,1),"") | F8: {=MATCH(1,(pages!$A$1:$A$957=games[[#This Row],[r]])*(pages!$B$1:$B$957=games[[#This Row],[field]]),0)} -> 10 | G8: =INDEX(pages!$L$1:$L$957,games[[#This Row],[ind]]) -> FALSE | H8: =_xlfn.IFNA(IF(LEN(games[[#This Row],[pair]])=3,INDEX(teams[id],MATCH(LEFT(games[[#This Row],[pair]]),teams[char],0)),""),"") | I8: =_xlfn.IFNA(IF(LEN(games[[#This Row],[pair]])=3,INDEX(teams[id],MATCH(RIGHT(games[[#This Row],[pair]]),teams[char],0)),""),"") | J8: =IF(games[[#This Row],[played]],INDEX(pages!$I$1:$I$759,games[[#This Row],[ind]]),"") | K8: =IF(games[[#This Row],[played]],INDEX(pages!$J$1:$J$759,games[[#This Row],[ind]]),"") | L8: =INDEX(fields[char],MATCH(games[[#This Row],[field]],fields[field],0))&IF(games[[#This Row],[tag]]="-","","("&games[[#This Row],[tag]]&")") -> p()
A9: =A4+1 -> 2 | B9: bask | C9: =INDEX(fields[column],MATCH(games[[#This Row],[field]],fields[field],0)) -> 3 | D9: =_xlfn.IFNA(OFFSET(plan!$A$1,MATCH(games[[#This Row],[r]],plan!A:A,0)-1,games[[#This Row],[col]]+1+0),_xlfn.IFNA(OFFSET(plan!$A$1,MATCH(games[[#This Row],[r]],plan!H:H,0)-1,games[[#This Row],[col]]+1+7),_xlfn.IFNA(OFFSET(plan!$A$1,MATCH(games[[#This Row],[r]],plan!O:O,0)-1,games[[#This Row],[col]]+1+14),_xlfn.IFNA(OFFSET(plan!$A$1,MATCH(games[[#This Row],[r]],plan!V:V,0)-1,games[[#This Row],[col]]+1+21),"")))) -> 0 | E9: =IF(LEN(games[[#This Row],[pair]])=3,MID(games[[#This Row],[pair]],2,1),"") | F9: {=MATCH(1,(pages!$A$1:$A$957=games[[#This Row],[r]])*(pages!$B$1:$B$957=games[[#This Row],[field]]),0)} -> 11 | G9: =INDEX(pages!$L$1:$L$957,games[[#This Row],[ind]]) -> FALSE | H9: =_xlfn.IFNA(IF(LEN(games[[#This Row],[pair]])=3,INDEX(teams[id],MATCH(LEFT(games[[#This Row],[pair]]),teams[char],0)),""),"") | I9: =_xlfn.IFNA(IF(LEN(games[[#This Row],[pair]])=3,INDEX(teams[id],MATCH(RIGHT(games[[#This Row],[pair]]),teams[char],0)),""),"") | J9: =IF(games[[#This Row],[played]],INDEX(pages!$I$1:$I$759,games[[#This Row],[ind]]),"") | K9: =IF(games[[#This Row],[played]],INDEX(pages!$J$1:$J$759,games[[#This Row],[ind]]),"") | L9: =INDEX(fields[char],MATCH(games[[#This Row],[field]],fields[field],0))&IF(games[[#This Row],[tag]]="-","","("&games[[#This Row],[tag]]&")") -> k()
A10: =A5+1 -> 2 | B10: voll | C10: =INDEX(fields[column],MATCH(games[[#This Row],[field]],fields[field],0)) -> 4 | D10: =_xlfn.IFNA(OFFSET(plan!$A$1,MATCH(games[[#This Row],[r]],plan!A:A,0)-1,games[[#This Row],[col]]+1+0),_xlfn.IFNA(OFFSET(plan!$A$1,MATCH(games[[#This Row],[r]],plan!H:H,0)-1,games[[#This Row],[col]]+1+7),_xlfn.IFNA(OFFSET(plan!$A$1,MATCH(games[[#This Row],[r]],plan!O:O,0)-1,games[[#This Row],[col]]+1+14),_xlfn.IFNA(OFFSET(plan!$A$1,MATCH(games[[#This Row],[r]],plan!V:V,0)-1,games[[#This Row],[col]]+1+21),"")))) -> 0 | E10: =IF(LEN(games[[#This Row],[pair]])=3,MID(games[[#This Row],[pair]],2,1),"") | F10: {=MATCH(1,(pages!$A$1:$A$957=games[[#This Row],[r]])*(pages!$B$1:$B$957=games[[#This Row],[field]]),0)} -> 12 | G10: =INDEX(pages!$L$1:$L$957,games[[#This Row],[ind]]) -> FALSE | H10: =_xlfn.IFNA(IF(LEN(games[[#This Row],[pair]])=3,INDEX(teams[id],MATCH(LEFT(games[[#This Row],[pair]]),teams[char],0)),""),"") | I10: =_xlfn.IFNA(IF(LEN(games[[#This Row],[pair]])=3,INDEX(teams[id],MATCH(RIGHT(games[[#This Row],[pair]]),teams[char],0)),""),"") | J10: =IF(games[[#This Row],[played]],INDEX(pages!$I$1:$I$759,games[[#This Row],[ind]]),"") | K10: =IF(games[[#This Row],[played]],INDEX(pages!$J$1:$J$759,games[[#This Row],[ind]]),"") | L10: =INDEX(fields[char],MATCH(games[[#This Row],[field]],fields[field],0))&IF(games[[#This Row],[tag]]="-","","("&games[[#This Row],[tag]]&")") -> v()
A11: =A6+1 -> 2 | B11: base | C11: =INDEX(fields[column],MATCH(games[[#This Row],[field]],fields[field],0)) -> 5 | D11: =_xlfn.IFNA(OFFSET(plan!$A$1,MATCH(games[[#This Row],[r]],plan!A:A,0)-1,games[[#This Row],[col]]+1+0),_xlfn.IFNA(OFFSET(plan!$A$1,MATCH(games[[#This Row],[r]],plan!H:H,0)-1,games[[#This Row],[col]]+1+7),_xlfn.IFNA(OFFSET(plan!$A$1,MATCH(games[[#This Row],[r]],plan!O:O,0)-1,games[[#This Row],[col]]+1+14),_xlfn.IFNA(OFFSET(plan!$A$1,MATCH(games[[#This Row],[r]],plan!V:V,0)-1,games[[#This Row],[col]]+1+21),"")))) -> 0 | E11: =IF(LEN(games[[#This Row],[pair]])=3,MID(games[[#This Row],[pair]],2,1),"") | F11: {=MATCH(1,(pages!$A$1:$A$957=games[[#This Row],[r]])*(pages!$B$1:$B$957=games[[#This Row],[field]]),0)} -> 13 | G11: =INDEX(pages!$L$1:$L$957,games[[#This Row],[ind]]) -> FALSE | H11: =_xlfn.IFNA(IF(LEN(games[[#This Row],[pair]])=3,INDEX(teams[id],MATCH(LEFT(games[[#This Row],[pair]]),teams[char],0)),""),"") | I11: =_xlfn.IFNA(IF(LEN(games[[#This Row],[pair]])=3,INDEX(teams[id],MATCH(RIGHT(games[[#This Row],[pair]]),teams[char],0)),""),"") | J11: =IF(games[[#This Row],[played]],INDEX(pages!$I$1:$I$759,games[[#This Row],[ind]]),"") | K11: =IF(games[[#This Row],[played]],INDEX(pages!$J$1:$J$759,games[[#This Row],[ind]]),"") | L11: =INDEX(fields[char],MATCH(games[[#This Row],[field]],fields[field],0))&IF(games[[#This Row],[tag]]="-","","("&games[[#This Row],[tag]]&")") -> m()
A12: =A7+1 -> 3 | B12: fold | C12: =INDEX(fields[column],MATCH(games[[#This Row],[field]],fields[field],0)) -> 1 | D12: =_xlfn.IFNA(OFFSET(plan!$A$1,MATCH(games[[#This Row],[r]],plan!A:A,0)-1,games[[#This Row],[col]]+1+0),_xlfn.IFNA(OFFSET(plan!$A$1,MATCH(games[[#This Row],[r]],plan!H:H,0)-1,games[[#This Row],[col]]+1+7),_xlfn.IFNA(OFFSET(plan!$A$1,MATCH(games[[#This Row],[r]],plan!O:O,0)-1,games[[#This Row],[col]]+1+14),_xlfn.IFNA(OFFSET(plan!$A$1,MATCH(games[[#This Row],[r]],plan!V:V,0)-1,games[[#This Row],[col]]+1+21),"")))) -> 0 | E12: =IF(LEN(games[[#This Row],[pair]])=3,MID(games[[#This Row],[pair]],2,1),"") | F12: {=MATCH(1,(pages!$A$1:$A$957=games[[#This Row],[r]])*(pages!$B$1:$B$957=games[[#This Row],[field]]),0)} -> 14 | G12: =INDEX(pages!$L$1:$L$957,games[[#This Row],[ind]]) -> FALSE | H12: =_xlfn.IFNA(IF(LEN(games[[#This Row],[pair]])=3,INDEX(teams[id],MATCH(LEFT(games[[#This Row],[pair]]),teams[char],0)),""),"") | I12: =_xlfn.IFNA(IF(LEN(games[[#This Row],[pair]])=3,INDEX(teams[id],MATCH(RIGHT(games[[#This Row],[pair]]),teams[char],0)),""),"") | J12: =IF(games[[#This Row],[played]],INDEX(pages!$I$1:$I$759,games[[#This Row],[ind]]),"") | K12: =IF(games[[#This Row],[played]],INDEX(pages!$J$1:$J$759,games[[#This Row],[ind]]),"") | L12: =INDEX(fields[char],MATCH(games[[#This Row],[field]],fields[field],0))&IF(games[[#This Row],[tag]]="-","","("&games[[#This Row],[tag]]&")") -> p()
A13: =A8+1 -> 3 | B13: fnew | C13: =INDEX(fields[column],MATCH(games[[#This Row],[field]],fields[field],0)) -> 2 | D13: =_xlfn.IFNA(OFFSET(plan!$A$1,MATCH(games[[#This Row],[r]],plan!A:A,0)-1,games[[#This Row],[col]]+1+0),_xlfn.IFNA(OFFSET(plan!$A$1,MATCH(games[[#This Row],[r]],plan!H:H,0)-1,games[[#This Row],[col]]+1+7),_xlfn.IFNA(OFFSET(plan!$A$1,MATCH(games[[#This Row],[r]],plan!O:O,0)-1,games[[#This Row],[col]]+1+14),_xlfn.IFNA(OFFSET(plan!$A$1,MATCH(games[[#This Row],[r]],plan!V:V,0)-1,games[[#This Row],[col]]+1+21),"")))) -> 0 | E13: =IF(LEN(games[[#This Row],[pair]])=3,MID(games[[#This Row],[pair]],2,1),"") | F13: {=MATCH(1,(pages!$A$1:$A$957=games[[#This Row],[r]])*(pages!$B$1:$B$957=games[[#This Row],[field]]),0)} -> 15 | G13: =INDEX(pages!$L$1:$L$957,games[[#This Row],[ind]]) -> FALSE | H13: =_xlfn.IFNA(IF(LEN(games[[#This Row],[pair]])=3,INDEX(teams[id],MATCH(LEFT(games[[#This Row],[pair]]),teams[char],0)),""),"") | I13: =_xlfn.IFNA(IF(LEN(games[[#This Row],[pair]])=3,INDEX(teams[id],MATCH(RIGHT(games[[#This Row],[pair]]),teams[char],0)),""),"") | J13: =IF(games[[#This Row],[played]],INDEX(pages!$I$1:$I$759,games[[#This Row],[ind]]),"") | K13: =IF(games[[#This Row],[played]],INDEX(pages!$J$1:$J$759,games[[#This Row],[ind]]),"") | L13: =INDEX(fields[char],MATCH(games[[#This Row],[field]],fields[field],0))&IF(games[[#This Row],[tag]]="-","","("&games[[#This Row],[tag]]&")") -> p()
A14: =A9+1 -> 3 | B14: bask | C14: =INDEX(fields[column],MATCH(games[[#This Row],[field]],fields[field],0)) -> 3 | D14: =_xlfn.IFNA(OFFSET(plan!$A$1,MATCH(games[[#This Row],[r]],plan!A:A,0)-1,games[[#This Row],[col]]+1+0),_xlfn.IFNA(OFFSET(plan!$A$1,MATCH(games[[#This Row],[r]],plan!H:H,0)-1,games[[#This Row],[col]]+1+7),_xlfn.IFNA(OFFSET(plan!$A$1,MATCH(games[[#This Row],[r]],plan!O:O,0)-1,games[[#This Row],[col]]+1+14),_xlfn.IFNA(OFFSET(plan!$A$1,MATCH(games[[#This Row],[r]],plan!V:V,0)-1,games[[#This Row],[col]]+1+21),"")))) -> 0 | E14: =IF(LEN(games[[#This Row],[pair]])=3,MID(games[[#This Row],[pair]],2,1),"") | F14: {=MATCH(1,(pages!$A$1:$A$957=games[[#This Row],[r]])*(pages!$B$1:$B$957=games[[#This Row],[field]]),0)} -> 16 | G14: =INDEX(pages!$L$1:$L$957,games[[#This Row],[ind]]) -> FALSE | H14: =_xlfn.IFNA(IF(LEN(games[[#This Row],[pair]])=3,INDEX(teams[id],MATCH(LEFT(games[[#This Row],[pair]]),teams[char],0)),""),"") | I14: =_xlfn.IFNA(IF(LEN(games[[#This Row],[pair]])=3,INDEX(teams[id],MATCH(RIGHT(games[[#This Row],[pair]]),teams[char],0)),""),"") | J14: =IF(games[[#This Row],[played]],INDEX(pages!$I$1:$I$759,games[[#This Row],[ind]]),"") | K14: =IF(games[[#This Row],[played]],INDEX(pages!$J$1:$J$759,games[[#This Row],[ind]]),"") | L14: =INDEX(fields[char],MATCH(games[[#This Row],[field]],fields[field],0))&IF(games[[#This Row],[tag]]="-","","("&games[[#This Row],[tag]]&")") -> k()
A15: =A10+1 -> 3 | B15: voll | C15: =INDEX(fields[column],MATCH(games[[#This Row],[field]],fields[field],0)) -> 4 | D15: =_xlfn.IFNA(OFFSET(plan!$A$1,MATCH(games[[#This Row],[r]],plan!A:A,0)-1,games[[#This Row],[col]]+1+0),_xlfn.IFNA(OFFSET(plan!$A$1,MATCH(games[[#This Row],[r]],plan!H:H,0)-1,games[[#This Row],[col]]+1+7),_xlfn.IFNA(OFFSET(plan!$A$1,MATCH(games[[#This Row],[r]],plan!O:O,0)-1,games[[#This Row],[col]]+1+14),_xlfn.IFNA(OFFSET(plan!$A$1,MATCH(games[[#This Row],[r]],plan!V:V,0)-1,games[[#This Row],[col]]+1+21),"")))) -> 0 | E15: =IF(LEN(games[[#This Row],[pair]])=3,MID(games[[#This Row],[pair]],2,1),"") | F15: {=MATCH(1,(pages!$A$1:$A$957=games[[#This Row],[r]])*(pages!$B$1:$B$957=games[[#This Row],[field]]),0)} -> 17 | G15: =INDEX(pages!$L$1:$L$957,games[[#This Row],[ind]]) -> FALSE | H15: =_xlfn.IFNA(IF(LEN(games[[#This Row],[pair]])=3,INDEX(teams[id],MATCH(LEFT(games[[#This Row],[pair]]),teams[char],0)),""),"") | I15: =_xlfn.IFNA(IF(LEN(games[[#This Row],[pair]])=3,INDEX(teams[id],MATCH(RIGHT(games[[#This Row],[pair]]),teams[char],0)),""),"") | J15: =IF(games[[#This Row],[played]],INDEX(pages!$I$1:$I$759,games[[#This Row],[ind]]),"") | K15: =IF(games[[#This Row],[played]],INDEX(pages!$J$1:$J$759,games[[#This Row],[ind]]),"") | L15: =INDEX(fields[char],MATCH(games[[#This Row],[field]],fields[field],0))&IF(games[[#This Row],[tag]]="-","","("&games[[#This Row],[tag]]&")") -> v()
A16: =A11+1 -> 3 | B16: base | C16: =INDEX(fields[column],MATCH(games[[#This Row],[field]],fields[field],0)) -> 5 | D16: =_xlfn.IFNA(OFFSET(plan!$A$1,MATCH(games[[#This Row],[r]],plan!A:A,0)-1,games[[#This Row],[col]]+1+0),_xlfn.IFNA(OFFSET(plan!$A$1,MATCH(games[[#This Row],[r]],plan!H:H,0)-1,games[[#This Row],[col]]+1+7),_xlfn.IFNA(OFFSET(plan!$A$1,MATCH(games[[#This Row],[r]],plan!O:O,0)-1,games[[#This Row],[col]]+1+14),_xlfn.IFNA(OFFSET(plan!$A$1,MATCH(games[[#This Row],[r]],plan!V:V,0)-1,games[[#This Row],[col]]+1+21),"")))) -> 0 | E16: =IF(LEN(games[[#This Row],[pair]])=3,MID(games[[#This Row],[pair]],2,1),"") | F16: {=MATCH(1,(pages!$A$1:$A$957=games[[#This Row],[r]])*(pages!$B$1:$B$957=games[[#This Row],[field]]),0)} -> 18 | G16: =INDEX(pages!$L$1:$L$957,games[[#This Row],[ind]]) -> FALSE | H16: =_xlfn.IFNA(IF(LEN(games[[#This Row],[pair]])=3,INDEX(teams[id],MATCH(LEFT(games[[#This Row],[pair]]),teams[char],0)),""),"") | I16: =_xlfn.IFNA(IF(LEN(games[[#This Row],[pair]])=3,INDEX(teams[id],MATCH(RIGHT(games[[#This Row],[pair]]),teams[char],0)),""),"") | J16: =IF(games[[#This Row],[played]],INDEX(pages!$I$1:$I$759,games[[#This Row],[ind]]),"") | K16: =IF(games[[#This Row],[played]],INDEX(pages!$J$1:$J$759,games[[#This Row],[ind]]),"") | L16: =INDEX(fields[char],MATCH(games[[#This Row],[field]],fields[field],0))&IF(games[[#This Row],[tag]]="-","","("&games[[#This Row],[tag]]&")") -> m()
A17: =A12+1 -> 4 | B17: fold | C17: =INDEX(fields[column],MATCH(games[[#This Row],[field]],fields[field],0)) -> 1 | D17: =_xlfn.IFNA(OFFSET(plan!$A$1,MATCH(games[[#This Row],[r]],plan!A:A,0)-1,games[[#This Row],[col]]+1+0),_xlfn.IFNA(OFFSET(plan!$A$1,MATCH(games[[#This Row],[r]],plan!H:H,0)-1,games[[#This Row],[col]]+1+7),_xlfn.IFNA(OFFSET(plan!$A$1,MATCH(games[[#This Row],[r]],plan!O:O,0)-1,games[[#This Row],[col]]+1+14),_xlfn.IFNA(OFFSET(plan!$A$1,MATCH(games[[#This Row],[r]],plan!V:V,0)-1,games[[#This Row],[col]]+1+21),"")))) -> 0 | E17: =IF(LEN(games[[#This Row],[pair]])=3,MID(games[[#This Row],[pair]],2,1),"") | F17: {=MATCH(1,(pages!$A$1:$A$957=games[[#This Row],[r]])*(pages!$B$1:$B$957=games[[#This Row],[field]]),0)} -> 19 | G17: =INDEX(pages!$L$1:$L$957,games[[#This Row],[ind]]) -> FALSE | H17: =_xlfn.IFNA(IF(LEN(games[[#This Row],[pair]])=3,INDEX(teams[id],MATCH(LEFT(games[[#This Row],[pair]]),teams[char],0)),""),"") | I17: =_xlfn.IFNA(IF(LEN(games[[#This Row],[pair]])=3,INDEX(teams[id],MATCH(RIGHT(games[[#This Row],[pair]]),teams[char],0)),""),"") | J17: =IF(games[[#This Row],[played]],INDEX(pages!$I$1:$I$759,games[[#This Row],[ind]]),"") | K17: =IF(games[[#This Row],[played]],INDEX(pages!$J$1:$J$759,games[[#This Row],[ind]]),"") | L17: =INDEX(fields[char],MATCH(games[[#This Row],[field]],fields[field],0))&IF(games[[#This Row],[tag]]="-","","("&games[[#This Row],[tag]]&")") -> p()
A18: =A13+1 -> 4 | B18: fnew | C18: =INDEX(fields[column],MATCH(games[[#This Row],[field]],fields[field],0)) -> 2 | D18: =_xlfn.IFNA(OFFSET(plan!$A$1,MATCH(games[[#This Row],[r]],plan!A:A,0)-1,games[[#This Row],[col]]+1+0),_xlfn.IFNA(OFFSET(plan!$A$1,MATCH(games[[#This Row],[r]],plan!H:H,0)-1,games[[#This Row],[col]]+1+7),_xlfn.IFNA(OFFSET(plan!$A$1,MATCH(games[[#This Row],[r]],plan!O:O,0)-1,games[[#This Row],[col]]+1+14),_xlfn.IFNA(OFFSET(plan!$A$1,MATCH(games[[#This Row],[r]],plan!V:V,0)-1,games[[#This Row],[col]]+1+21),"")))) -> 0 | E18: =IF(LEN(games[[#This Row],[pair]])=3,MID(games[[#This Row],[pair]],2,1),"") | F18: {=MATCH(1,(pages!$A$1:$A$957=games[[#This Row],[r]])*(pages!$B$1:$B$957=games[[#This Row],[field]]),0)} -> 20 | G18: =INDEX(pages!$L$1:$L$957,games[[#This Row],[ind]]) -> FALSE | H18: =_xlfn.IFNA(IF(LEN(games[[#This Row],[pair]])=3,INDEX(teams[id],MATCH(LEFT(games[[#This Row],[pair]]),teams[char],0)),""),"") | I18: =_xlfn.IFNA(IF(LEN(games[[#This Row],[pair]])=3,INDEX(teams[id],MATCH(RIGHT(games[[#This Row],[pair]]),teams[char],0)),""),"") | J18: =IF(games[[#This Row],[played]],INDEX(pages!$I$1:$I$759,games[[#This Row],[ind]]),"") | K18: =IF(games[[#This Row],[played]],INDEX(pages!$J$1:$J$759,games[[#This Row],[ind]]),"") | L18: =INDEX(fields[char],MATCH(games[[#This Row],[field]],fields[field],0))&IF(games[[#This Row],[tag]]="-","","("&games[[#This Row],[tag]]&")") -> p()
... A241: =A236+1 -> 48 | B241: base | C241: =INDEX(fields[column],MATCH(games[[#This Row],[field]],fields[field],0)) -> 5 | D241: =_xlfn.IFNA(OFFSET(plan!$A$1,MATCH(games[[#This Row],[r]],plan!A:A,0)-1,games[[#This Row],[col]]+1+0),_xlfn.IFNA(OFFSET(plan!$A$1,MATCH(games[[#This Row],[r]],plan!H:H,0)-1,games[[#This Row],[col]]+1+7),_xlfn.IFNA(OFFSET(plan!$A$1,MATCH(games[[#This Row],[r]],plan!O:O,0)-1,games[[#This Row],[col]]+1+14),_xlfn.IFNA(OFFSET(plan!$A$1,MATCH(games[[#This Row],[r]],plan!V:V,0)-1,games[[#This Row],[col]]+1+21),"")))) -> 0 | E241: =IF(LEN(games[[#This Row],[pair]])=3,MID(games[[#This Row],[pair]],2,1),"") | F241: {=MATCH(1,(pages!$A$1:$A$957=games[[#This Row],[r]])*(pages!$B$1:$B$957=games[[#This Row],[field]]),0)} -> 265 | G241: =INDEX(pages!$L$1:$L$957,games[[#This Row],[ind]]) -> FALSE | H241: =_xlfn.IFNA(IF(LEN(games[[#This Row],[pair]])=3,INDEX(teams[id],MATCH(LEFT(games[[#This Row],[pair]]),teams[char],0)),""),"") | I241: =_xlfn.IFNA(IF(LEN(games[[#This Row],[pair]])=3,INDEX(teams[id],MATCH(RIGHT(games[[#This Row],[pair]]),teams[char],0)),""),"") | J241: =IF(games[[#This Row],[played]],INDEX(pages!$I$1:$I$759,games[[#This Row],[ind]]),"") | K241: =IF(games[[#This Row],[played]],INDEX(pages!$J$1:$J$759,games[[#This Row],[ind]]),"") | L241: =INDEX(fields[char],MATCH(games[[#This Row],[field]],fields[field],0))&IF(games[[#This Row],[tag]]="-","","("&games[[#This Row],[tag]]&")") -> m()

Sheet pages
A1: r | B1: field | E1: th | G1: ta | I1: sh | J1: sa | K1: referee | L1: played
C3: =plan!B2 -> 46244
A4: 1 | B4: fold | C4: Πρωί Α' | D4: =INDEX(fields[name],MATCH($B4,fields[field],0)) -> Π Ποδόσφαιρο | E4: {=IF(ISBLANK($A4),"",INDEX(games[th],MATCH(1,(games[r]=$A4)*(games[field]=$B4),0)))} | F4: =_xlfn.IFNA(INDEX(teams[name],MATCH(E4,teams[id],0)),"") | G4: {=IF(ISBLANK($A4),"",INDEX(games[ta],MATCH(1,(games[r]=$A4)*(games[field]=$B4),0)))} | H4: =_xlfn.IFNA(INDEX(teams[name],MATCH(G4,teams[id],0)),"") | L4: =NOT(OR(ISBLANK($I4),ISBLANK($J4))) -> FALSE
A5: 1 | B5: fnew | D5: =INDEX(fields[name],MATCH($B5,fields[field],0)) -> Κ Ποδόσφαιρο | E5: {=IF(ISBLANK($A5),"",INDEX(games[th],MATCH(1,(games[r]=$A5)*(games[field]=$B5),0)))} | F5: =_xlfn.IFNA(INDEX(teams[name],MATCH(E5,teams[id],0)),"") | G5: {=IF(ISBLANK($A5),"",INDEX(games[ta],MATCH(1,(games[r]=$A5)*(games[field]=$B5),0)))} | H5: =_xlfn.IFNA(INDEX(teams[name],MATCH(G5,teams[id],0)),"") | L5: =NOT(OR(ISBLANK($I5),ISBLANK($J5))) -> FALSE
A6: 1 | B6: bask | D6: =INDEX(fields[name],MATCH($B6,fields[field],0)) -> Μπάσκετ | E6: {=IF(ISBLANK($A6),"",INDEX(games[th],MATCH(1,(games[r]=$A6)*(games[field]=$B6),0)))} | F6: =_xlfn.IFNA(INDEX(teams[name],MATCH(E6,teams[id],0)),"") | G6: {=IF(ISBLANK($A6),"",INDEX(games[ta],MATCH(1,(games[r]=$A6)*(games[field]=$B6),0)))} | H6: =_xlfn.IFNA(INDEX(teams[name],MATCH(G6,teams[id],0)),"") | L6: =NOT(OR(ISBLANK($I6),ISBLANK($J6))) -> FALSE
A7: 1 | B7: voll | D7: =INDEX(fields[name],MATCH($B7,fields[field],0)) -> Βόλεϊ | E7: {=IF(ISBLANK($A7),"",INDEX(games[th],MATCH(1,(games[r]=$A7)*(games[field]=$B7),0)))} | F7: =_xlfn.IFNA(INDEX(teams[name],MATCH(E7,teams[id],0)),"") | G7: {=IF(ISBLANK($A7),"",INDEX(games[ta],MATCH(1,(games[r]=$A7)*(games[field]=$B7),0)))} | H7: =_xlfn.IFNA(INDEX(teams[name],MATCH(G7,teams[id],0)),"") | L7: =NOT(OR(ISBLANK($I7),ISBLANK($J7))) -> FALSE
A8: 1 | B8: base | D8: =INDEX(fields[name],MATCH($B8,fields[field],0)) -> Μπέιζμπολ | E8: {=IF(ISBLANK($A8),"",INDEX(games[th],MATCH(1,(games[r]=$A8)*(games[field]=$B8),0)))} | F8: =_xlfn.IFNA(INDEX(teams[name],MATCH(E8,teams[id],0)),"") | G8: {=IF(ISBLANK($A8),"",INDEX(games[ta],MATCH(1,(games[r]=$A8)*(games[field]=$B8),0)))} | H8: =_xlfn.IFNA(INDEX(teams[name],MATCH(G8,teams[id],0)),"") | L8: =NOT(OR(ISBLANK($I8),ISBLANK($J8))) -> FALSE
A9: 2 | B9: fold | C9: Πρωί Β' | D9: =INDEX(fields[name],MATCH($B9,fields[field],0)) -> Π Ποδόσφαιρο | E9: {=IF(ISBLANK($A9),"",INDEX(games[th],MATCH(1,(games[r]=$A9)*(games[field]=$B9),0)))} | F9: =_xlfn.IFNA(INDEX(teams[name],MATCH(E9,teams[id],0)),"") | G9: {=IF(ISBLANK($A9),"",INDEX(games[ta],MATCH(1,(games[r]=$A9)*(games[field]=$B9),0)))} | H9: =_xlfn.IFNA(INDEX(teams[name],MATCH(G9,teams[id],0)),"") | L9: =NOT(OR(ISBLANK($I9),ISBLANK($J9))) -> FALSE
A10: 2 | B10: fnew | D10: =INDEX(fields[name],MATCH($B10,fields[field],0)) -> Κ Ποδόσφαιρο | E10: {=IF(ISBLANK($A10),"",INDEX(games[th],MATCH(1,(games[r]=$A10)*(games[field]=$B10),0)))} | F10: =_xlfn.IFNA(INDEX(teams[name],MATCH(E10,teams[id],0)),"") | G10: {=IF(ISBLANK($A10),"",INDEX(games[ta],MATCH(1,(games[r]=$A10)*(games[field]=$B10),0)))} | H10: =_xlfn.IFNA(INDEX(teams[name],MATCH(G10,teams[id],0)),"") | L10: =NOT(OR(ISBLANK($I10),ISBLANK($J10))) -> FALSE
A11: 2 | B11: bask | D11: =INDEX(fields[name],MATCH($B11,fields[field],0)) -> Μπάσκετ | E11: {=IF(ISBLANK($A11),"",INDEX(games[th],MATCH(1,(games[r]=$A11)*(games[field]=$B11),0)))} | F11: =_xlfn.IFNA(INDEX(teams[name],MATCH(E11,teams[id],0)),"") | G11: {=IF(ISBLANK($A11),"",INDEX(games[ta],MATCH(1,(games[r]=$A11)*(games[field]=$B11),0)))} | H11: =_xlfn.IFNA(INDEX(teams[name],MATCH(G11,teams[id],0)),"") | L11: =NOT(OR(ISBLANK($I11),ISBLANK($J11))) -> FALSE
A12: 2 | B12: voll | D12: =INDEX(fields[name],MATCH($B12,fields[field],0)) -> Βόλεϊ | E12: {=IF(ISBLANK($A12),"",INDEX(games[th],MATCH(1,(games[r]=$A12)*(games[field]=$B12),0)))} | F12: =_xlfn.IFNA(INDEX(teams[name],MATCH(E12,teams[id],0)),"") | G12: {=IF(ISBLANK($A12),"",INDEX(games[ta],MATCH(1,(games[r]=$A12)*(games[field]=$B12),0)))} | H12: =_xlfn.IFNA(INDEX(teams[name],MATCH(G12,teams[id],0)),"") | L12: =NOT(OR(ISBLANK($I12),ISBLANK($J12))) -> FALSE
A13: 2 | B13: base | D13: =INDEX(fields[name],MATCH($B13,fields[field],0)) -> Μπέιζμπολ | E13: {=IF(ISBLANK($A13),"",INDEX(games[th],MATCH(1,(games[r]=$A13)*(games[field]=$B13),0)))} | F13: =_xlfn.IFNA(INDEX(teams[name],MATCH(E13,teams[id],0)),"") | G13: {=IF(ISBLANK($A13),"",INDEX(games[ta],MATCH(1,(games[r]=$A13)*(games[field]=$B13),0)))} | H13: =_xlfn.IFNA(INDEX(teams[name],MATCH(G13,teams[id],0)),"") | L13: =NOT(OR(ISBLANK($I13),ISBLANK($J13))) -> FALSE
A14: 3 | B14: fold | C14: Απόγ. Α' | D14: =INDEX(fields[name],MATCH($B14,fields[field],0)) -> Π Ποδόσφαιρο | E14: {=IF(ISBLANK($A14),"",INDEX(games[th],MATCH(1,(games[r]=$A14)*(games[field]=$B14),0)))} | F14: =_xlfn.IFNA(INDEX(teams[name],MATCH(E14,teams[id],0)),"") | G14: {=IF(ISBLANK($A14),"",INDEX(games[ta],MATCH(1,(games[r]=$A14)*(games[field]=$B14),0)))} | H14: =_xlfn.IFNA(INDEX(teams[name],MATCH(G14,teams[id],0)),"") | L14: =NOT(OR(ISBLANK($I14),ISBLANK($J14))) -> FALSE
A15: 3 | B15: fnew | D15: =INDEX(fields[name],MATCH($B15,fields[field],0)) -> Κ Ποδόσφαιρο | E15: {=IF(ISBLANK($A15),"",INDEX(games[th],MATCH(1,(games[r]=$A15)*(games[field]=$B15),0)))} | F15: =_xlfn.IFNA(INDEX(teams[name],MATCH(E15,teams[id],0)),"") | G15: {=IF(ISBLANK($A15),"",INDEX(games[ta],MATCH(1,(games[r]=$A15)*(games[field]=$B15),0)))} | H15: =_xlfn.IFNA(INDEX(teams[name],MATCH(G15,teams[id],0)),"") | L15: =NOT(OR(ISBLANK($I15),ISBLANK($J15))) -> FALSE
A16: 3 | B16: bask | D16: =INDEX(fields[name],MATCH($B16,fields[field],0)) -> Μπάσκετ | E16: {=IF(ISBLANK($A16),"",INDEX(games[th],MATCH(1,(games[r]=$A16)*(games[field]=$B16),0)))} | F16: =_xlfn.IFNA(INDEX(teams[name],MATCH(E16,teams[id],0)),"") | G16: {=IF(ISBLANK($A16),"",INDEX(games[ta],MATCH(1,(games[r]=$A16)*(games[field]=$B16),0)))} | H16: =_xlfn.IFNA(INDEX(teams[name],MATCH(G16,teams[id],0)),"") | L16: =NOT(OR(ISBLANK($I16),ISBLANK($J16))) -> FALSE
A17: 3 | B17: voll | D17: =INDEX(fields[name],MATCH($B17,fields[field],0)) -> Βόλεϊ | E17: {=IF(ISBLANK($A17),"",INDEX(games[th],MATCH(1,(games[r]=$A17)*(games[field]=$B17),0)))} | F17: =_xlfn.IFNA(INDEX(teams[name],MATCH(E17,teams[id],0)),"") | G17: {=IF(ISBLANK($A17),"",INDEX(games[ta],MATCH(1,(games[r]=$A17)*(games[field]=$B17),0)))} | H17: =_xlfn.IFNA(INDEX(teams[name],MATCH(G17,teams[id],0)),"") | L17: =NOT(OR(ISBLANK($I17),ISBLANK($J17))) -> FALSE
A18: 3 | B18: base | D18: =INDEX(fields[name],MATCH($B18,fields[field],0)) -> Μπέιζμπολ | E18: {=IF(ISBLANK($A18),"",INDEX(games[th],MATCH(1,(games[r]=$A18)*(games[field]=$B18),0)))} | F18: =_xlfn.IFNA(INDEX(teams[name],MATCH(E18,teams[id],0)),"") | G18: {=IF(ISBLANK($A18),"",INDEX(games[ta],MATCH(1,(games[r]=$A18)*(games[field]=$B18),0)))} | H18: =_xlfn.IFNA(INDEX(teams[name],MATCH(G18,teams[id],0)),"") | L18: =NOT(OR(ISBLANK($I18),ISBLANK($J18))) -> FALSE
A19: 4 | B19: fold | C19: Απόγ. Β' | D19: =INDEX(fields[name],MATCH($B19,fields[field],0)) -> Π Ποδόσφαιρο | E19: {=IF(ISBLANK($A19),"",INDEX(games[th],MATCH(1,(games[r]=$A19)*(games[field]=$B19),0)))} | F19: =_xlfn.IFNA(INDEX(teams[name],MATCH(E19,teams[id],0)),"") | G19: {=IF(ISBLANK($A19),"",INDEX(games[ta],MATCH(1,(games[r]=$A19)*(games[field]=$B19),0)))} | H19: =_xlfn.IFNA(INDEX(teams[name],MATCH(G19,teams[id],0)),"") | L19: =NOT(OR(ISBLANK($I19),ISBLANK($J19))) -> FALSE
A20: 4 | B20: fnew | D20: =INDEX(fields[name],MATCH($B20,fields[field],0)) -> Κ Ποδόσφαιρο | E20: {=IF(ISBLANK($A20),"",INDEX(games[th],MATCH(1,(games[r]=$A20)*(games[field]=$B20),0)))} | F20: =_xlfn.IFNA(INDEX(teams[name],MATCH(E20,teams[id],0)),"") | G20: {=IF(ISBLANK($A20),"",INDEX(games[ta],MATCH(1,(games[r]=$A20)*(games[field]=$B20),0)))} | H20: =_xlfn.IFNA(INDEX(teams[name],MATCH(G20,teams[id],0)),"") | L20: =NOT(OR(ISBLANK($I20),ISBLANK($J20))) -> FALSE
A21: 4 | B21: bask | D21: =INDEX(fields[name],MATCH($B21,fields[field],0)) -> Μπάσκετ | E21: {=IF(ISBLANK($A21),"",INDEX(games[th],MATCH(1,(games[r]=$A21)*(games[field]=$B21),0)))} | F21: =_xlfn.IFNA(INDEX(teams[name],MATCH(E21,teams[id],0)),"") | G21: {=IF(ISBLANK($A21),"",INDEX(games[ta],MATCH(1,(games[r]=$A21)*(games[field]=$B21),0)))} | H21: =_xlfn.IFNA(INDEX(teams[name],MATCH(G21,teams[id],0)),"") | L21: =NOT(OR(ISBLANK($I21),ISBLANK($J21))) -> FALSE
A22: 4 | B22: voll | D22: =INDEX(fields[name],MATCH($B22,fields[field],0)) -> Βόλεϊ | E22: {=IF(ISBLANK($A22),"",INDEX(games[th],MATCH(1,(games[r]=$A22)*(games[field]=$B22),0)))} | F22: =_xlfn.IFNA(INDEX(teams[name],MATCH(E22,teams[id],0)),"") | G22: {=IF(ISBLANK($A22),"",INDEX(games[ta],MATCH(1,(games[r]=$A22)*(games[field]=$B22),0)))} | H22: =_xlfn.IFNA(INDEX(teams[name],MATCH(G22,teams[id],0)),"") | L22: =NOT(OR(ISBLANK($I22),ISBLANK($J22))) -> FALSE
A23: 4 | B23: base | D23: =INDEX(fields[name],MATCH($B23,fields[field],0)) -> Μπέιζμπολ | E23: {=IF(ISBLANK($A23),"",INDEX(games[th],MATCH(1,(games[r]=$A23)*(games[field]=$B23),0)))} | F23: =_xlfn.IFNA(INDEX(teams[name],MATCH(E23,teams[id],0)),"") | G23: {=IF(ISBLANK($A23),"",INDEX(games[ta],MATCH(1,(games[r]=$A23)*(games[field]=$B23),0)))} | H23: =_xlfn.IFNA(INDEX(teams[name],MATCH(G23,teams[id],0)),"") | L23: =NOT(OR(ISBLANK($I23),ISBLANK($J23))) -> FALSE
C25: =C3+1 -> 46245
A26: =A4+4 -> 5 | B26: fold | C26: Πρωί Α' | D26: =INDEX(fields[name],MATCH($B26,fields[field],0)) -> Π Ποδόσφαιρο | E26: {=IF(ISBLANK($A26),"",INDEX(games[th],MATCH(1,(games[r]=$A26)*(games[field]=$B26),0)))} | F26: =_xlfn.IFNA(INDEX(teams[name],MATCH(E26,teams[id],0)),"") | G26: {=IF(ISBLANK($A26),"",INDEX(games[ta],MATCH(1,(games[r]=$A26)*(games[field]=$B26),0)))} | H26: =_xlfn.IFNA(INDEX(teams[name],MATCH(G26,teams[id],0)),"") | L26: =NOT(OR(ISBLANK($I26),ISBLANK($J26))) -> FALSE
A27: =A5+4 -> 5 | B27: fnew | D27: =INDEX(fields[name],MATCH($B27,fields[field],0)) -> Κ Ποδόσφαιρο | E27: {=IF(ISBLANK($A27),"",INDEX(games[th],MATCH(1,(games[r]=$A27)*(games[field]=$B27),0)))} | F27: =_xlfn.IFNA(INDEX(teams[name],MATCH(E27,teams[id],0)),"") | G27: {=IF(ISBLANK($A27),"",INDEX(games[ta],MATCH(1,(games[r]=$A27)*(games[field]=$B27),0)))} | H27: =_xlfn.IFNA(INDEX(teams[name],MATCH(G27,teams[id],0)),"") | L27: =NOT(OR(ISBLANK($I27),ISBLANK($J27))) -> FALSE
A28: =A6+4 -> 5 | B28: bask | D28: =INDEX(fields[name],MATCH($B28,fields[field],0)) -> Μπάσκετ | E28: {=IF(ISBLANK($A28),"",INDEX(games[th],MATCH(1,(games[r]=$A28)*(games[field]=$B28),0)))} | F28: =_xlfn.IFNA(INDEX(teams[name],MATCH(E28,teams[id],0)),"") | G28: {=IF(ISBLANK($A28),"",INDEX(games[ta],MATCH(1,(games[r]=$A28)*(games[field]=$B28),0)))} | H28: =_xlfn.IFNA(INDEX(teams[name],MATCH(G28,teams[id],0)),"") | L28: =NOT(OR(ISBLANK($I28),ISBLANK($J28))) -> FALSE
A29: =A7+4 -> 5 | B29: voll | D29: =INDEX(fields[name],MATCH($B29,fields[field],0)) -> Βόλεϊ | E29: {=IF(ISBLANK($A29),"",INDEX(games[th],MATCH(1,(games[r]=$A29)*(games[field]=$B29),0)))} | F29: =_xlfn.IFNA(INDEX(teams[name],MATCH(E29,teams[id],0)),"") | G29: {=IF(ISBLANK($A29),"",INDEX(games[ta],MATCH(1,(games[r]=$A29)*(games[field]=$B29),0)))} | H29: =_xlfn.IFNA(INDEX(teams[name],MATCH(G29,teams[id],0)),"") | L29: =NOT(OR(ISBLANK($I29),ISBLANK($J29))) -> FALSE
A30: =A8+4 -> 5 | B30: base | D30: =INDEX(fields[name],MATCH($B30,fields[field],0)) -> Μπέιζμπολ | E30: {=IF(ISBLANK($A30),"",INDEX(games[th],MATCH(1,(games[r]=$A30)*(games[field]=$B30),0)))} | F30: =_xlfn.IFNA(INDEX(teams[name],MATCH(E30,teams[id],0)),"") | G30: {=IF(ISBLANK($A30),"",INDEX(games[ta],MATCH(1,(games[r]=$A30)*(games[field]=$B30),0)))} | H30: =_xlfn.IFNA(INDEX(teams[name],MATCH(G30,teams[id],0)),"") | L30: =NOT(OR(ISBLANK($I30),ISBLANK($J30))) -> FALSE
A31: =A9+4 -> 6 | B31: fold | C31: Πρωί Β' | D31: =INDEX(fields[name],MATCH($B31,fields[field],0)) -> Π Ποδόσφαιρο | E31: {=IF(ISBLANK($A31),"",INDEX(games[th],MATCH(1,(games[r]=$A31)*(games[field]=$B31),0)))} | F31: =_xlfn.IFNA(INDEX(teams[name],MATCH(E31,teams[id],0)),"") | G31: {=IF(ISBLANK($A31),"",INDEX(games[ta],MATCH(1,(games[r]=$A31)*(games[field]=$B31),0)))} | H31: =_xlfn.IFNA(INDEX(teams[name],MATCH(G31,teams[id],0)),"") | L31: =NOT(OR(ISBLANK($I31),ISBLANK($J31))) -> FALSE
A32: =A10+4 -> 6 | B32: fnew | D32: =INDEX(fields[name],MATCH($B32,fields[field],0)) -> Κ Ποδόσφαιρο | E32: {=IF(ISBLANK($A32),"",INDEX(games[th],MATCH(1,(games[r]=$A32)*(games[field]=$B32),0)))} | F32: =_xlfn.IFNA(INDEX(teams[name],MATCH(E32,teams[id],0)),"") | G32: {=IF(ISBLANK($A32),"",INDEX(games[ta],MATCH(1,(games[r]=$A32)*(games[field]=$B32),0)))} | H32: =_xlfn.IFNA(INDEX(teams[name],MATCH(G32,teams[id],0)),"") | L32: =NOT(OR(ISBLANK($I32),ISBLANK($J32))) -> FALSE
A33: =A11+4 -> 6 | B33: bask | D33: =INDEX(fields[name],MATCH($B33,fields[field],0)) -> Μπάσκετ | E33: {=IF(ISBLANK($A33),"",INDEX(games[th],MATCH(1,(games[r]=$A33)*(games[field]=$B33),0)))} | F33: =_xlfn.IFNA(INDEX(teams[name],MATCH(E33,teams[id],0)),"") | G33: {=IF(ISBLANK($A33),"",INDEX(games[ta],MATCH(1,(games[r]=$A33)*(games[field]=$B33),0)))} | H33: =_xlfn.IFNA(INDEX(teams[name],MATCH(G33,teams[id],0)),"") | L33: =NOT(OR(ISBLANK($I33),ISBLANK($J33))) -> FALSE
A34: =A12+4 -> 6 | B34: voll | D34: =INDEX(fields[name],MATCH($B34,fields[field],0)) -> Βόλεϊ | E34: {=IF(ISBLANK($A34),"",INDEX(games[th],MATCH(1,(games[r]=$A34)*(games[field]=$B34),0)))} | F34: =_xlfn.IFNA(INDEX(teams[name],MATCH(E34,teams[id],0)),"") | G34: {=IF(ISBLANK($A34),"",INDEX(games[ta],MATCH(1,(games[r]=$A34)*(games[field]=$B34),0)))} | H34: =_xlfn.IFNA(INDEX(teams[name],MATCH(G34,teams[id],0)),"") | L34: =NOT(OR(ISBLANK($I34),ISBLANK($J34))) -> FALSE
A35: =A13+4 -> 6 | B35: base | D35: =INDEX(fields[name],MATCH($B35,fields[field],0)) -> Μπέιζμπολ | E35: {=IF(ISBLANK($A35),"",INDEX(games[th],MATCH(1,(games[r]=$A35)*(games[field]=$B35),0)))} | F35: =_xlfn.IFNA(INDEX(teams[name],MATCH(E35,teams[id],0)),"") | G35: {=IF(ISBLANK($A35),"",INDEX(games[ta],MATCH(1,(games[r]=$A35)*(games[field]=$B35),0)))} | H35: =_xlfn.IFNA(INDEX(teams[name],MATCH(G35,teams[id],0)),"") | L35: =NOT(OR(ISBLANK($I35),ISBLANK($J35))) -> FALSE
A36: =A14+4 -> 7 | B36: fold | C36: Απόγ. Α' | D36: =INDEX(fields[name],MATCH($B36,fields[field],0)) -> Π Ποδόσφαιρο | E36: {=IF(ISBLANK($A36),"",INDEX(games[th],MATCH(1,(games[r]=$A36)*(games[field]=$B36),0)))} | F36: =_xlfn.IFNA(INDEX(teams[name],MATCH(E36,teams[id],0)),"") | G36: {=IF(ISBLANK($A36),"",INDEX(games[ta],MATCH(1,(games[r]=$A36)*(games[field]=$B36),0)))} | H36: =_xlfn.IFNA(INDEX(teams[name],MATCH(G36,teams[id],0)),"") | L36: =NOT(OR(ISBLANK($I36),ISBLANK($J36))) -> FALSE
A37: =A15+4 -> 7 | B37: fnew | D37: =INDEX(fields[name],MATCH($B37,fields[field],0)) -> Κ Ποδόσφαιρο | E37: {=IF(ISBLANK($A37),"",INDEX(games[th],MATCH(1,(games[r]=$A37)*(games[field]=$B37),0)))} | F37: =_xlfn.IFNA(INDEX(teams[name],MATCH(E37,teams[id],0)),"") | G37: {=IF(ISBLANK($A37),"",INDEX(games[ta],MATCH(1,(games[r]=$A37)*(games[field]=$B37),0)))} | H37: =_xlfn.IFNA(INDEX(teams[name],MATCH(G37,teams[id],0)),"") | L37: =NOT(OR(ISBLANK($I37),ISBLANK($J37))) -> FALSE
A38: =A16+4 -> 7 | B38: bask | D38: =INDEX(fields[name],MATCH($B38,fields[field],0)) -> Μπάσκετ | E38: {=IF(ISBLANK($A38),"",INDEX(games[th],MATCH(1,(games[r]=$A38)*(games[field]=$B38),0)))} | F38: =_xlfn.IFNA(INDEX(teams[name],MATCH(E38,teams[id],0)),"") | G38: {=IF(ISBLANK($A38),"",INDEX(games[ta],MATCH(1,(games[r]=$A38)*(games[field]=$B38),0)))} | H38: =_xlfn.IFNA(INDEX(teams[name],MATCH(G38,teams[id],0)),"") | L38: =NOT(OR(ISBLANK($I38),ISBLANK($J38))) -> FALSE
A39: =A17+4 -> 7 | B39: voll | D39: =INDEX(fields[name],MATCH($B39,fields[field],0)) -> Βόλεϊ | E39: {=IF(ISBLANK($A39),"",INDEX(games[th],MATCH(1,(games[r]=$A39)*(games[field]=$B39),0)))} | F39: =_xlfn.IFNA(INDEX(teams[name],MATCH(E39,teams[id],0)),"") | G39: {=IF(ISBLANK($A39),"",INDEX(games[ta],MATCH(1,(games[r]=$A39)*(games[field]=$B39),0)))} | H39: =_xlfn.IFNA(INDEX(teams[name],MATCH(G39,teams[id],0)),"") | L39: =NOT(OR(ISBLANK($I39),ISBLANK($J39))) -> FALSE
A40: =A18+4 -> 7 | B40: base | D40: =INDEX(fields[name],MATCH($B40,fields[field],0)) -> Μπέιζμπολ | E40: {=IF(ISBLANK($A40),"",INDEX(games[th],MATCH(1,(games[r]=$A40)*(games[field]=$B40),0)))} | F40: =_xlfn.IFNA(INDEX(teams[name],MATCH(E40,teams[id],0)),"") | G40: {=IF(ISBLANK($A40),"",INDEX(games[ta],MATCH(1,(games[r]=$A40)*(games[field]=$B40),0)))} | H40: =_xlfn.IFNA(INDEX(teams[name],MATCH(G40,teams[id],0)),"") | L40: =NOT(OR(ISBLANK($I40),ISBLANK($J40))) -> FALSE
A41: =A19+4 -> 8 | B41: fold | C41: Απόγ. Β' | D41: =INDEX(fields[name],MATCH($B41,fields[field],0)) -> Π Ποδόσφαιρο | E41: {=IF(ISBLANK($A41),"",INDEX(games[th],MATCH(1,(games[r]=$A41)*(games[field]=$B41),0)))} | F41: =_xlfn.IFNA(INDEX(teams[name],MATCH(E41,teams[id],0)),"") | G41: {=IF(ISBLANK($A41),"",INDEX(games[ta],MATCH(1,(games[r]=$A41)*(games[field]=$B41),0)))} | H41: =_xlfn.IFNA(INDEX(teams[name],MATCH(G41,teams[id],0)),"") | L41: =NOT(OR(ISBLANK($I41),ISBLANK($J41))) -> FALSE
A42: =A20+4 -> 8 | B42: fnew | D42: =INDEX(fields[name],MATCH($B42,fields[field],0)) -> Κ Ποδόσφαιρο | E42: {=IF(ISBLANK($A42),"",INDEX(games[th],MATCH(1,(games[r]=$A42)*(games[field]=$B42),0)))} | F42: =_xlfn.IFNA(INDEX(teams[name],MATCH(E42,teams[id],0)),"") | G42: {=IF(ISBLANK($A42),"",INDEX(games[ta],MATCH(1,(games[r]=$A42)*(games[field]=$B42),0)))} | H42: =_xlfn.IFNA(INDEX(teams[name],MATCH(G42,teams[id],0)),"") | L42: =NOT(OR(ISBLANK($I42),ISBLANK($J42))) -> FALSE
...

Sheet points
L1: αγνοειται
B2: Championship | D2: Football | M2: Basketball | U2: Volleyball | AC2: Baseball | AJ2: Championship
B3: team | D3: PLD | E3: W | F3: D | G3: L | H3: GF | I3: GA | J3: GD | K3: PTS | L3: RNK | M3: PLD | N3: W | O3: L | P3: GF | Q3: GA | R3: GD | S3: PTS | T3: RNK | U3: PLD | V3: W | W3: L | X3: GF | Y3: GA | Z3: GD | AA3: PTS | AB3: RNK | AC3: PLD | AD3: W | AE3: L | AF3: GF | AG3: GA | AH3: GD | AI3: PTS | AJ3: team
B4: 1 | C4: =INDEX(teams[name],MATCH(B4,teams[id],0)) -> 0 | D4: =E4+F4+G4 -> 0 | E4: {=SUM((games[sport]="p")*(games[played])*((games[th]=$B4)*(games[sh]>games[sa])+(games[ta]=$B4)*(games[sa]>games[sh])))} -> 0 | F4: {=SUM((games[sport]="p")*(games[played])*((games[th]=$B4)*(games[sh]=games[sa])+(games[ta]=$B4)*(games[sa]=games[sh])))} -> 0 | G4: {=SUM((games[sport]="p")*(games[played])*((games[th]=$B4)*(games[sh]<games[sa])+(games[ta]=$B4)*(games[sa]<games[sh])))} -> 0 | H4: =SUMIFS(games[sh],games[sport],"p",games[th],$B4)+SUMIFS(games[sa],games[sport],"p",games[ta],$B4) -> 0 | I4: =SUMIFS(games[sa],games[sport],"p",games[th],$B4)+SUMIFS(games[sh],games[sport],"p",games[ta],$B4) -> 0 | J4: =H4-I4 -> 0 | K4: =3*E4+1*F4+0*G4 -> 0 | L4: =_xlfn.RANK.EQ(K4,$K$4:$K$8) -> 1 | M4: =N4+O4 -> 0 | N4: {=SUM((games[sport]="k")*(games[played])*((games[th]=$B4)*(games[sh]>games[sa])+(games[ta]=$B4)*(games[sa]>games[sh])))} -> 0 | O4: {=SUM((games[sport]="k")*(games[played])*((games[th]=$B4)*(games[sh]<games[sa])+(games[ta]=$B4)*(games[sa]<games[sh])))} -> 0 | P4: =SUMIFS(games[sh],games[sport],"k",games[th],$B4)+SUMIFS(games[sa],games[sport],"k",games[ta],$B4) -> 0 | Q4: =SUMIFS(games[sa],games[sport],"k",games[th],$B4)+SUMIFS(games[sh],games[sport],"k",games[ta],$B4) -> 0 | R4: =P4-Q4 -> 0 | S4: =2*N4+1*O4 -> 0 | T4: =_xlfn.RANK.EQ(S4,$S$4:$S$8) -> 1 | U4: =V4+W4 -> 0 | V4: {=SUM((games[sport]="v")*(games[played])*((games[th]=$B4)*(games[sh]>games[sa])+(games[ta]=$B4)*(games[sa]>games[sh])))} -> 0 | W4: {=SUM((games[sport]="v")*(games[played])*((games[th]=$B4)*(games[sh]<games[sa])+(games[ta]=$B4)*(games[sa]<games[sh])))} -> 0 | X4: =SUMIFS(games[sh],games[sport],"v",games[th],$B4)+SUMIFS(games[sa],games[sport],"v",games[ta],$B4) -> 0 | Y4: =SUMIFS(games[sa],games[sport],"v",games[th],$B4)+SUMIFS(games[sh],games[sport],"v",games[ta],$B4) -> 0 | Z4: =X4-Y4 -> 0 | AA4: =U4+W4+Z4 -> 0 | AB4: =_xlfn.RANK.EQ(AA4,$AA$4:$AA$8) -> 1 | AC4: =AD4+AE4 -> 0 | AD4: {=SUM((games[sport]="m")*(games[played])*((games[th]=$B4)*(games[sh]>games[sa])+(games[ta]=$B4)*(games[sa]>games[sh])))} -> 0 | AE4: {=SUM((games[sport]="m")*(games[played])*((games[th]=$B4)*(games[sh]<games[sa])+(games[ta]=$B4)*(games[sa]<games[sh])))} -> 0 | AF4: =SUMIFS(games[sh],games[sport],"m",games[th],$B4)+SUMIFS(games[sa],games[sport],"m",games[ta],$B4) -> 0 | AG4: =SUMIFS(games[sa],games[sport],"m",games[th],$B4)+SUMIFS(games[sh],games[sport],"m",games[ta],$B4) -> 0 | AH4: =AF4-AG4 -> 0 | AI4: =2*AD4+1*AE4 -> 0 | AJ4: 1 | AK4: =AJ18 -> 0
B5: 2 | C5: =INDEX(teams[name],MATCH(B5,teams[id],0)) -> 0 | D5: =E5+F5+G5 -> 0 | E5: {=SUM((games[sport]="p")*(games[played])*((games[th]=$B5)*(games[sh]>games[sa])+(games[ta]=$B5)*(games[sa]>games[sh])))} -> 0 | F5: {=SUM((games[sport]="p")*(games[played])*((games[th]=$B5)*(games[sh]=games[sa])+(games[ta]=$B5)*(games[sa]=games[sh])))} -> 0 | G5: {=SUM((games[sport]="p")*(games[played])*((games[th]=$B5)*(games[sh]<games[sa])+(games[ta]=$B5)*(games[sa]<games[sh])))} -> 0 | H5: =SUMIFS(games[sh],games[sport],"p",games[th],$B5)+SUMIFS(games[sa],games[sport],"p",games[ta],$B5) -> 0 | I5: =SUMIFS(games[sa],games[sport],"p",games[th],$B5)+SUMIFS(games[sh],games[sport],"p",games[ta],$B5) -> 0 | J5: =H5-I5 -> 0 | K5: =3*E5+1*F5+0*G5 -> 0 | L5: =_xlfn.RANK.EQ(K5,$K$4:$K$8) -> 1 | M5: =N5+O5 -> 0 | N5: {=SUM((games[sport]="k")*(games[played])*((games[th]=$B5)*(games[sh]>games[sa])+(games[ta]=$B5)*(games[sa]>games[sh])))} -> 0 | O5: {=SUM((games[sport]="k")*(games[played])*((games[th]=$B5)*(games[sh]<games[sa])+(games[ta]=$B5)*(games[sa]<games[sh])))} -> 0 | P5: =SUMIFS(games[sh],games[sport],"k",games[th],$B5)+SUMIFS(games[sa],games[sport],"k",games[ta],$B5) -> 0 | Q5: =SUMIFS(games[sa],games[sport],"k",games[th],$B5)+SUMIFS(games[sh],games[sport],"k",games[ta],$B5) -> 0 | R5: =P5-Q5 -> 0 | S5: =2*N5+1*O5 -> 0 | T5: =_xlfn.RANK.EQ(S5,$S$4:$S$8) -> 1 | U5: =V5+W5 -> 0 | V5: {=SUM((games[sport]="v")*(games[played])*((games[th]=$B5)*(games[sh]>games[sa])+(games[ta]=$B5)*(games[sa]>games[sh])))} -> 0 | W5: {=SUM((games[sport]="v")*(games[played])*((games[th]=$B5)*(games[sh]<games[sa])+(games[ta]=$B5)*(games[sa]<games[sh])))} -> 0 | X5: =SUMIFS(games[sh],games[sport],"v",games[th],$B5)+SUMIFS(games[sa],games[sport],"v",games[ta],$B5) -> 0 | Y5: =SUMIFS(games[sa],games[sport],"v",games[th],$B5)+SUMIFS(games[sh],games[sport],"v",games[ta],$B5) -> 0 | Z5: =X5-Y5 -> 0 | AA5: =U5+W5+Z5 -> 0 | AB5: =_xlfn.RANK.EQ(AA5,$AA$4:$AA$8) -> 1 | AC5: =AD5+AE5 -> 0 | AD5: {=SUM((games[sport]="m")*(games[played])*((games[th]=$B5)*(games[sh]>games[sa])+(games[ta]=$B5)*(games[sa]>games[sh])))} -> 0 | AE5: {=SUM((games[sport]="m")*(games[played])*((games[th]=$B5)*(games[sh]<games[sa])+(games[ta]=$B5)*(games[sa]<games[sh])))} -> 0 | AF5: =SUMIFS(games[sh],games[sport],"m",games[th],$B5)+SUMIFS(games[sa],games[sport],"m",games[ta],$B5) -> 0 | AG5: =SUMIFS(games[sa],games[sport],"m",games[th],$B5)+SUMIFS(games[sh],games[sport],"m",games[ta],$B5) -> 0 | AH5: =AF5-AG5 -> 0 | AI5: =2*AD5+1*AE5 -> 0 | AJ5: 2 | AK5: =INDEX(teams[name],MATCH(AJ5,teams[id],0)) -> 0
B6: 3 | C6: =INDEX(teams[name],MATCH(B6,teams[id],0)) -> 0 | D6: =E6+F6+G6 -> 0 | E6: {=SUM((games[sport]="p")*(games[played])*((games[th]=$B6)*(games[sh]>games[sa])+(games[ta]=$B6)*(games[sa]>games[sh])))} -> 0 | F6: {=SUM((games[sport]="p")*(games[played])*((games[th]=$B6)*(games[sh]=games[sa])+(games[ta]=$B6)*(games[sa]=games[sh])))} -> 0 | G6: {=SUM((games[sport]="p")*(games[played])*((games[th]=$B6)*(games[sh]<games[sa])+(games[ta]=$B6)*(games[sa]<games[sh])))} -> 0 | H6: =SUMIFS(games[sh],games[sport],"p",games[th],$B6)+SUMIFS(games[sa],games[sport],"p",games[ta],$B6) -> 0 | I6: =SUMIFS(games[sa],games[sport],"p",games[th],$B6)+SUMIFS(games[sh],games[sport],"p",games[ta],$B6) -> 0 | J6: =H6-I6 -> 0 | K6: =3*E6+1*F6+0*G6 -> 0 | L6: =_xlfn.RANK.EQ(K6,$K$4:$K$8) -> 1 | M6: =N6+O6 -> 0 | N6: {=SUM((games[sport]="k")*(games[played])*((games[th]=$B6)*(games[sh]>games[sa])+(games[ta]=$B6)*(games[sa]>games[sh])))} -> 0 | O6: {=SUM((games[sport]="k")*(games[played])*((games[th]=$B6)*(games[sh]<games[sa])+(games[ta]=$B6)*(games[sa]<games[sh])))} -> 0 | P6: =SUMIFS(games[sh],games[sport],"k",games[th],$B6)+SUMIFS(games[sa],games[sport],"k",games[ta],$B6) -> 0 | Q6: =SUMIFS(games[sa],games[sport],"k",games[th],$B6)+SUMIFS(games[sh],games[sport],"k",games[ta],$B6) -> 0 | R6: =P6-Q6 -> 0 | S6: =2*N6+1*O6 -> 0 | T6: =_xlfn.RANK.EQ(S6,$S$4:$S$8) -> 1 | U6: =V6+W6 -> 0 | V6: {=SUM((games[sport]="v")*(games[played])*((games[th]=$B6)*(games[sh]>games[sa])+(games[ta]=$B6)*(games[sa]>games[sh])))} -> 0 | W6: {=SUM((games[sport]="v")*(games[played])*((games[th]=$B6)*(games[sh]<games[sa])+(games[ta]=$B6)*(games[sa]<games[sh])))} -> 0 | X6: =SUMIFS(games[sh],games[sport],"v",games[th],$B6)+SUMIFS(games[sa],games[sport],"v",games[ta],$B6) -> 0 | Y6: =SUMIFS(games[sa],games[sport],"v",games[th],$B6)+SUMIFS(games[sh],games[sport],"v",games[ta],$B6) -> 0 | Z6: =X6-Y6 -> 0 | AA6: =U6+W6+Z6 -> 0 | AB6: =_xlfn.RANK.EQ(AA6,$AA$4:$AA$8) -> 1 | AC6: =AD6+AE6 -> 0 | AD6: {=SUM((games[sport]="m")*(games[played])*((games[th]=$B6)*(games[sh]>games[sa])+(games[ta]=$B6)*(games[sa]>games[sh])))} -> 0 | AE6: {=SUM((games[sport]="m")*(games[played])*((games[th]=$B6)*(games[sh]<games[sa])+(games[ta]=$B6)*(games[sa]<games[sh])))} -> 0 | AF6: =SUMIFS(games[sh],games[sport],"m",games[th],$B6)+SUMIFS(games[sa],games[sport],"m",games[ta],$B6) -> 0 | AG6: =SUMIFS(games[sa],games[sport],"m",games[th],$B6)+SUMIFS(games[sh],games[sport],"m",games[ta],$B6) -> 0 | AH6: =AF6-AG6 -> 0 | AI6: =2*AD6+1*AE6 -> 0 | AJ6: 3 | AK6: =INDEX(teams[name],MATCH(AJ6,teams[id],0)) -> 0
B7: 4 | C7: =INDEX(teams[name],MATCH(B7,teams[id],0)) -> 0 | D7: =E7+F7+G7 -> 0 | E7: {=SUM((games[sport]="p")*(games[played])*((games[th]=$B7)*(games[sh]>games[sa])+(games[ta]=$B7)*(games[sa]>games[sh])))} -> 0 | F7: {=SUM((games[sport]="p")*(games[played])*((games[th]=$B7)*(games[sh]=games[sa])+(games[ta]=$B7)*(games[sa]=games[sh])))} -> 0 | G7: {=SUM((games[sport]="p")*(games[played])*((games[th]=$B7)*(games[sh]<games[sa])+(games[ta]=$B7)*(games[sa]<games[sh])))} -> 0 | H7: =SUMIFS(games[sh],games[sport],"p",games[th],$B7)+SUMIFS(games[sa],games[sport],"p",games[ta],$B7) -> 0 | I7: =SUMIFS(games[sa],games[sport],"p",games[th],$B7)+SUMIFS(games[sh],games[sport],"p",games[ta],$B7) -> 0 | J7: =H7-I7 -> 0 | K7: =3*E7+1*F7+0*G7 -> 0 | L7: =_xlfn.RANK.EQ(K7,$K$4:$K$8) -> 1 | M7: =N7+O7 -> 0 | N7: {=SUM((games[sport]="k")*(games[played])*((games[th]=$B7)*(games[sh]>games[sa])+(games[ta]=$B7)*(games[sa]>games[sh])))} -> 0 | O7: {=SUM((games[sport]="k")*(games[played])*((games[th]=$B7)*(games[sh]<games[sa])+(games[ta]=$B7)*(games[sa]<games[sh])))} -> 0 | P7: =SUMIFS(games[sh],games[sport],"k",games[th],$B7)+SUMIFS(games[sa],games[sport],"k",games[ta],$B7) -> 0 | Q7: =SUMIFS(games[sa],games[sport],"k",games[th],$B7)+SUMIFS(games[sh],games[sport],"k",games[ta],$B7) -> 0 | R7: =P7-Q7 -> 0 | S7: =2*N7+1*O7 -> 0 | T7: =_xlfn.RANK.EQ(S7,$S$4:$S$8) -> 1 | U7: =V7+W7 -> 0 | V7: {=SUM((games[sport]="v")*(games[played])*((games[th]=$B7)*(games[sh]>games[sa])+(games[ta]=$B7)*(games[sa]>games[sh])))} -> 0 | W7: {=SUM((games[sport]="v")*(games[played])*((games[th]=$B7)*(games[sh]<games[sa])+(games[ta]=$B7)*(games[sa]<games[sh])))} -> 0 | X7: =SUMIFS(games[sh],games[sport],"v",games[th],$B7)+SUMIFS(games[sa],games[sport],"v",games[ta],$B7) -> 0 | Y7: =SUMIFS(games[sa],games[sport],"v",games[th],$B7)+SUMIFS(games[sh],games[sport],"v",games[ta],$B7) -> 0 | Z7: =X7-Y7 -> 0 | AA7: =U7+W7+Z7 -> 0 | AB7: =_xlfn.RANK.EQ(AA7,$AA$4:$AA$8) -> 1 | AC7: =AD7+AE7 -> 0 | AD7: {=SUM((games[sport]="m")*(games[played])*((games[th]=$B7)*(games[sh]>games[sa])+(games[ta]=$B7)*(games[sa]>games[sh])))} -> 0 | AE7: {=SUM((games[sport]="m")*(games[played])*((games[th]=$B7)*(games[sh]<games[sa])+(games[ta]=$B7)*(games[sa]<games[sh])))} -> 0 | AF7: =SUMIFS(games[sh],games[sport],"m",games[th],$B7)+SUMIFS(games[sa],games[sport],"m",games[ta],$B7) -> 0 | AG7: =SUMIFS(games[sa],games[sport],"m",games[th],$B7)+SUMIFS(games[sh],games[sport],"m",games[ta],$B7) -> 0 | AH7: =AF7-AG7 -> 0 | AI7: =2*AD7+1*AE7 -> 0 | AJ7: 4 | AK7: =INDEX(teams[name],MATCH(AJ7,teams[id],0)) -> 0
B8: 5 | C8: =INDEX(teams[name],MATCH(B8,teams[id],0)) -> 0 | D8: =E8+F8+G8 -> 0 | E8: {=SUM((games[sport]="p")*(games[played])*((games[th]=$B8)*(games[sh]>games[sa])+(games[ta]=$B8)*(games[sa]>games[sh])))} -> 0 | F8: {=SUM((games[sport]="p")*(games[played])*((games[th]=$B8)*(games[sh]=games[sa])+(games[ta]=$B8)*(games[sa]=games[sh])))} -> 0 | G8: {=SUM((games[sport]="p")*(games[played])*((games[th]=$B8)*(games[sh]<games[sa])+(games[ta]=$B8)*(games[sa]<games[sh])))} -> 0 | H8: =SUMIFS(games[sh],games[sport],"p",games[th],$B8)+SUMIFS(games[sa],games[sport],"p",games[ta],$B8) -> 0 | I8: =SUMIFS(games[sa],games[sport],"p",games[th],$B8)+SUMIFS(games[sh],games[sport],"p",games[ta],$B8) -> 0 | J8: =H8-I8 -> 0 | K8: =3*E8+1*F8+0*G8 -> 0 | L8: =_xlfn.RANK.EQ(K8,$K$4:$K$8) -> 1 | M8: =N8+O8 -> 0 | N8: {=SUM((games[sport]="k")*(games[played])*((games[th]=$B8)*(games[sh]>games[sa])+(games[ta]=$B8)*(games[sa]>games[sh])))} -> 0 | O8: {=SUM((games[sport]="k")*(games[played])*((games[th]=$B8)*(games[sh]<games[sa])+(games[ta]=$B8)*(games[sa]<games[sh])))} -> 0 | P8: =SUMIFS(games[sh],games[sport],"k",games[th],$B8)+SUMIFS(games[sa],games[sport],"k",games[ta],$B8) -> 0 | Q8: =SUMIFS(games[sa],games[sport],"k",games[th],$B8)+SUMIFS(games[sh],games[sport],"k",games[ta],$B8) -> 0 | R8: =P8-Q8 -> 0 | S8: =2*N8+1*O8 -> 0 | T8: =_xlfn.RANK.EQ(S8,$S$4:$S$8) -> 1 | U8: =V8+W8 -> 0 | V8: {=SUM((games[sport]="v")*(games[played])*((games[th]=$B8)*(games[sh]>games[sa])+(games[ta]=$B8)*(games[sa]>games[sh])))} -> 0 | W8: {=SUM((games[sport]="v")*(games[played])*((games[th]=$B8)*(games[sh]<games[sa])+(games[ta]=$B8)*(games[sa]<games[sh])))} -> 0 | X8: =SUMIFS(games[sh],games[sport],"v",games[th],$B8)+SUMIFS(games[sa],games[sport],"v",games[ta],$B8) -> 0 | Y8: =SUMIFS(games[sa],games[sport],"v",games[th],$B8)+SUMIFS(games[sh],games[sport],"v",games[ta],$B8) -> 0 | Z8: =X8-Y8 -> 0 | AA8: =U8+W8+Z8 -> 0 | AB8: =_xlfn.RANK.EQ(AA8,$AA$4:$AA$8) -> 1 | AC8: =AD8+AE8 -> 0 | AD8: {=SUM((games[sport]="m")*(games[played])*((games[th]=$B8)*(games[sh]>games[sa])+(games[ta]=$B8)*(games[sa]>games[sh])))} -> 0 | AE8: {=SUM((games[sport]="m")*(games[played])*((games[th]=$B8)*(games[sh]<games[sa])+(games[ta]=$B8)*(games[sa]<games[sh])))} -> 0 | AF8: =SUMIFS(games[sh],games[sport],"m",games[th],$B8)+SUMIFS(games[sa],games[sport],"m",games[ta],$B8) -> 0 | AG8: =SUMIFS(games[sa],games[sport],"m",games[th],$B8)+SUMIFS(games[sh],games[sport],"m",games[ta],$B8) -> 0 | AH8: =AF8-AG8 -> 0 | AI8: =2*AD8+1*AE8 -> 0 | AJ8: 5 | AK8: =INDEX(teams[name],MATCH(AJ8,teams[id],0)) -> 0
B9: team | D9: PLD | E9: W | F9: D | G9: L | H9: GF | I9: GA | J9: GD | K9: PTS | L9: RNK | M9: PLD | N9: W | O9: L | P9: GF | Q9: GA | R9: GD | S9: PTS | T9: RNK | U9: PLD | V9: W | W9: L | X9: GF | Y9: GA | Z9: GD | AA9: PTS | AB9: RNK | AC9: PLD | AD9: W | AE9: L | AF9: GF | AG9: GA | AH9: GD | AI9: PTS | AJ9: team
